ERROR - Error getting service details for dkr-uepo-test-internal-v3-ecs-common-blue-ApplicationECSService-ksVbI3TTrrdm in cluster dkr-cluster-PROJ-PLAN-internal-blue: An error occurred (TargetGroupNotFound) when calling the DescribeTargetGroups operation: One or more target groups not found
Traceback (most recent call last):
  File "C:\Users\ux186612\Documents\ecs3.py", line 216, in <module>
    main()
  File "C:\Users\ux186612\Documents\ecs3.py", line 208, in main
    service_details = future.result()
  File "C:\Program Files\Python310\lib\concurrent\futures\_base.py", line 451, in result
    return self.__get_result()
  File "C:\Program Files\Python310\lib\concurrent\futures\_base.py", line 403, in __get_result
    raise self._exception
  File "C:\Program Files\Python310\lib\concurrent\futures\thread.py", line 58, in run
    result = self.fn(*self.args, **self.kwargs)
  File "C:\Users\ux186612\Documents\ecs3.py", line 179, in process_services
    service_details_list.append(future.result())
  File "C:\Program Files\Python310\lib\concurrent\futures\_base.py", line 451, in result
    return self.__get_result()
  File "C:\Program Files\Python310\lib\concurrent\futures\_base.py", line 403, in __get_result
    raise self._exception
  File "C:\Program Files\Python310\lib\concurrent\futures\thread.py", line 58, in run
    result = self.fn(*self.args, **self.kwargs)
  File "C:\Users\ux186612\Documents\ecs3.py", line 158, in get_service_details
    if target_group_arn:
UnboundLocalError: local variable 'target_group_arn' referenced before assignment
